import 'package:firebase_auth/firebase_auth.dart';
import 'package:google_sign_in/google_sign_in.dart';

class AuthService {
  final FirebaseAuth _auth = FirebaseAuth.instance;

  Stream<User?> get authStateChanges => _auth.authStateChanges();

  User? get currentUser => _auth.currentUser;

  Future<void> signInWithEmail(String email, String password) async {
    try {
      await _auth.signInWithEmailAndPassword(email: email, password: password);
    } on FirebaseAuthException catch (e) {
      throw AuthExceptionHandler.handleException(e);
    }
  }

  Future<void> registerWithEmail(String email, String password) async {
    try {
      await _auth.createUserWithEmailAndPassword(
        email: email,
        password: password,
      );
    } on FirebaseAuthException catch (e) {
      throw AuthExceptionHandler.handleException(e);
    }
  }

  Future<void> signInWithGoogle() async {
    try {
      final googleUser = await GoogleSignIn().signIn();
      if (googleUser == null) return;

      final googleAuth = await googleUser.authentication;

      final credential = GoogleAuthProvider.credential(
        idToken: googleAuth.idToken,
        accessToken: googleAuth.accessToken,
      );

      await _auth.signInWithCredential(credential);
    } on FirebaseAuthException catch (e) {
      throw AuthExceptionHandler.handleException(e);
    }
  }

  Future<void> signOut() async {
    await _auth.signOut();
    await GoogleSignIn().signOut();
  }
}

class AuthExceptionHandler {
  static String handleException(FirebaseAuthException e) {
    switch (e.code) {
      case 'user-not-found':
        return 'No user found for that email.';
      case 'wrong-password':
        return 'Wrong password provided.';
      case 'email-already-in-use':
        return 'Email is already in use.';
      case 'invalid-email':
        return 'Invalid email address.';
      case 'weak-password':
        return 'The password is too weak.';
      case 'network-request-failed':
        return 'Check your internet connection.';
      default:
        return 'An unexpected error occurred.';
    }
  }
}
